2024-07-20 16:45:13,186 INFO    MainThread:23323 [wandb_setup.py:_flush():76] Current SDK version is 0.17.5
2024-07-20 16:45:13,186 INFO    MainThread:23323 [wandb_setup.py:_flush():76] Configure stats pid to 23323
2024-07-20 16:45:13,186 INFO    MainThread:23323 [wandb_setup.py:_flush():76] Loading settings from /Users/zend/.config/wandb/settings
2024-07-20 16:45:13,186 INFO    MainThread:23323 [wandb_setup.py:_flush():76] Loading settings from /Users/zend/Desktop/faster-pytorch/01Wandb/wandb/settings
2024-07-20 16:45:13,186 INFO    MainThread:23323 [wandb_setup.py:_flush():76] Loading settings from environment variables: {}
2024-07-20 16:45:13,186 INFO    MainThread:23323 [wandb_setup.py:_flush():76] Applying setup settings: {'_disable_service': False}
2024-07-20 16:45:13,186 INFO    MainThread:23323 [wandb_setup.py:_flush():76] Inferring run settings from compute environment: {'program': '<python with no main file>'}
2024-07-20 16:45:13,186 INFO    MainThread:23323 [wandb_setup.py:_flush():76] Applying login settings: {}
2024-07-20 16:45:13,186 INFO    MainThread:23323 [wandb_init.py:_log_setup():529] Logging user logs to /Users/zend/Desktop/faster-pytorch/01Wandb/wandb/run-20240720_164513-axrv0wdp/logs/debug.log
2024-07-20 16:45:13,186 INFO    MainThread:23323 [wandb_init.py:_log_setup():530] Logging internal logs to /Users/zend/Desktop/faster-pytorch/01Wandb/wandb/run-20240720_164513-axrv0wdp/logs/debug-internal.log
2024-07-20 16:45:13,186 INFO    MainThread:23323 [wandb_init.py:_jupyter_setup():475] configuring jupyter hooks <wandb.sdk.wandb_init._WandbInit object at 0x3507faff0>
2024-07-20 16:45:13,186 INFO    MainThread:23323 [wandb_init.py:init():569] calling init triggers
2024-07-20 16:45:13,186 INFO    MainThread:23323 [wandb_init.py:init():576] wandb.init called with sweep_config: {}
config: {'lr': 0.0001, 'epoch': 3, 'batch_size': 64}
2024-07-20 16:45:13,186 INFO    MainThread:23323 [wandb_init.py:init():619] starting backend
2024-07-20 16:45:13,186 INFO    MainThread:23323 [wandb_init.py:init():623] setting up manager
2024-07-20 16:45:13,187 INFO    MainThread:23323 [backend.py:_multiprocessing_setup():105] multiprocessing start_methods=spawn,fork,forkserver, using: spawn
2024-07-20 16:45:13,190 INFO    MainThread:23323 [wandb_init.py:init():631] backend started and connected
2024-07-20 16:45:13,196 INFO    MainThread:23323 [wandb_run.py:_label_probe_notebook():1334] probe notebook
2024-07-20 16:45:13,196 INFO    MainThread:23323 [wandb_run.py:_label_probe_notebook():1344] Unable to probe notebook: 'NoneType' object has no attribute 'get'
2024-07-20 16:45:13,196 INFO    MainThread:23323 [wandb_init.py:init():720] updated telemetry
2024-07-20 16:45:13,207 INFO    MainThread:23323 [wandb_init.py:init():753] communicating run to backend with 90.0 second timeout
2024-07-20 16:45:26,980 INFO    Thread-32 (wrapped_target):23323 [retry.py:__call__():172] Retry attempt failed:
Traceback (most recent call last):
  File "/Users/zend/Desktop/faster-pytorch/.pixi/envs/default/lib/python3.12/site-packages/urllib3/connectionpool.py", line 775, in urlopen
    self._prepare_proxy(conn)
  File "/Users/zend/Desktop/faster-pytorch/.pixi/envs/default/lib/python3.12/site-packages/urllib3/connectionpool.py", line 1044, in _prepare_proxy
    conn.connect()
  File "/Users/zend/Desktop/faster-pytorch/.pixi/envs/default/lib/python3.12/site-packages/urllib3/connection.py", line 652, in connect
    sock_and_verified = _ssl_wrap_socket_and_match_hostname(
                        ^^^^^^^^^^^^^^^^^^^^^^^^^^^^^^^^^^^^
  File "/Users/zend/Desktop/faster-pytorch/.pixi/envs/default/lib/python3.12/site-packages/urllib3/connection.py", line 805, in _ssl_wrap_socket_and_match_hostname
    ssl_sock = ssl_wrap_socket(
               ^^^^^^^^^^^^^^^^
  File "/Users/zend/Desktop/faster-pytorch/.pixi/envs/default/lib/python3.12/site-packages/urllib3/util/ssl_.py", line 465, in ssl_wrap_socket
    ssl_sock = _ssl_wrap_socket_impl(sock, context, tls_in_tls, server_hostname)
               ^^^^^^^^^^^^^^^^^^^^^^^^^^^^^^^^^^^^^^^^^^^^^^^^^^^^^^^^^^^^^^^^^
  File "/Users/zend/Desktop/faster-pytorch/.pixi/envs/default/lib/python3.12/site-packages/urllib3/util/ssl_.py", line 509, in _ssl_wrap_socket_impl
    return ssl_context.wrap_socket(sock, server_hostname=server_hostname)
           ^^^^^^^^^^^^^^^^^^^^^^^^^^^^^^^^^^^^^^^^^^^^^^^^^^^^^^^^^^^^^^
  File "/Users/zend/Desktop/faster-pytorch/.pixi/envs/default/lib/python3.12/ssl.py", line 455, in wrap_socket
    return self.sslsocket_class._create(
           ^^^^^^^^^^^^^^^^^^^^^^^^^^^^^
  File "/Users/zend/Desktop/faster-pytorch/.pixi/envs/default/lib/python3.12/ssl.py", line 1042, in _create
    self.do_handshake()
  File "/Users/zend/Desktop/faster-pytorch/.pixi/envs/default/lib/python3.12/ssl.py", line 1320, in do_handshake
    self._sslobj.do_handshake()
ConnectionResetError: [Errno 54] Connection reset by peer

During handling of the above exception, another exception occurred:

Traceback (most recent call last):
  File "/Users/zend/Desktop/faster-pytorch/.pixi/envs/default/lib/python3.12/site-packages/requests/adapters.py", line 667, in send
    resp = conn.urlopen(
           ^^^^^^^^^^^^^
  File "/Users/zend/Desktop/faster-pytorch/.pixi/envs/default/lib/python3.12/site-packages/urllib3/connectionpool.py", line 843, in urlopen
    retries = retries.increment(
              ^^^^^^^^^^^^^^^^^^
  File "/Users/zend/Desktop/faster-pytorch/.pixi/envs/default/lib/python3.12/site-packages/urllib3/util/retry.py", line 474, in increment
    raise reraise(type(error), error, _stacktrace)
          ^^^^^^^^^^^^^^^^^^^^^^^^^^^^^^^^^^^^^^^^
  File "/Users/zend/Desktop/faster-pytorch/.pixi/envs/default/lib/python3.12/site-packages/urllib3/util/util.py", line 38, in reraise
    raise value.with_traceback(tb)
  File "/Users/zend/Desktop/faster-pytorch/.pixi/envs/default/lib/python3.12/site-packages/urllib3/connectionpool.py", line 775, in urlopen
    self._prepare_proxy(conn)
  File "/Users/zend/Desktop/faster-pytorch/.pixi/envs/default/lib/python3.12/site-packages/urllib3/connectionpool.py", line 1044, in _prepare_proxy
    conn.connect()
  File "/Users/zend/Desktop/faster-pytorch/.pixi/envs/default/lib/python3.12/site-packages/urllib3/connection.py", line 652, in connect
    sock_and_verified = _ssl_wrap_socket_and_match_hostname(
                        ^^^^^^^^^^^^^^^^^^^^^^^^^^^^^^^^^^^^
  File "/Users/zend/Desktop/faster-pytorch/.pixi/envs/default/lib/python3.12/site-packages/urllib3/connection.py", line 805, in _ssl_wrap_socket_and_match_hostname
    ssl_sock = ssl_wrap_socket(
               ^^^^^^^^^^^^^^^^
  File "/Users/zend/Desktop/faster-pytorch/.pixi/envs/default/lib/python3.12/site-packages/urllib3/util/ssl_.py", line 465, in ssl_wrap_socket
    ssl_sock = _ssl_wrap_socket_impl(sock, context, tls_in_tls, server_hostname)
               ^^^^^^^^^^^^^^^^^^^^^^^^^^^^^^^^^^^^^^^^^^^^^^^^^^^^^^^^^^^^^^^^^
  File "/Users/zend/Desktop/faster-pytorch/.pixi/envs/default/lib/python3.12/site-packages/urllib3/util/ssl_.py", line 509, in _ssl_wrap_socket_impl
    return ssl_context.wrap_socket(sock, server_hostname=server_hostname)
           ^^^^^^^^^^^^^^^^^^^^^^^^^^^^^^^^^^^^^^^^^^^^^^^^^^^^^^^^^^^^^^
  File "/Users/zend/Desktop/faster-pytorch/.pixi/envs/default/lib/python3.12/ssl.py", line 455, in wrap_socket
    return self.sslsocket_class._create(
           ^^^^^^^^^^^^^^^^^^^^^^^^^^^^^
  File "/Users/zend/Desktop/faster-pytorch/.pixi/envs/default/lib/python3.12/ssl.py", line 1042, in _create
    self.do_handshake()
  File "/Users/zend/Desktop/faster-pytorch/.pixi/envs/default/lib/python3.12/ssl.py", line 1320, in do_handshake
    self._sslobj.do_handshake()
urllib3.exceptions.ProtocolError: ('Connection aborted.', ConnectionResetError(54, 'Connection reset by peer'))

During handling of the above exception, another exception occurred:

Traceback (most recent call last):
  File "/Users/zend/Desktop/faster-pytorch/.pixi/envs/default/lib/python3.12/site-packages/wandb/sdk/lib/retry.py", line 131, in __call__
    result = self._call_fn(*args, **kwargs)
             ^^^^^^^^^^^^^^^^^^^^^^^^^^^^^^
  File "/Users/zend/Desktop/faster-pytorch/.pixi/envs/default/lib/python3.12/site-packages/wandb/sdk/internal/internal_api.py", line 345, in execute
    return self.client.execute(*args, **kwargs)  # type: ignore
           ^^^^^^^^^^^^^^^^^^^^^^^^^^^^^^^^^^^^
  File "/Users/zend/Desktop/faster-pytorch/.pixi/envs/default/lib/python3.12/site-packages/wandb/vendor/gql-0.2.0/wandb_gql/client.py", line 52, in execute
    result = self._get_result(document, *args, **kwargs)
             ^^^^^^^^^^^^^^^^^^^^^^^^^^^^^^^^^^^^^^^^^^^
  File "/Users/zend/Desktop/faster-pytorch/.pixi/envs/default/lib/python3.12/site-packages/wandb/vendor/gql-0.2.0/wandb_gql/client.py", line 60, in _get_result
    return self.transport.execute(document, *args, **kwargs)
           ^^^^^^^^^^^^^^^^^^^^^^^^^^^^^^^^^^^^^^^^^^^^^^^^^
  File "/Users/zend/Desktop/faster-pytorch/.pixi/envs/default/lib/python3.12/site-packages/wandb/sdk/lib/gql_request.py", line 58, in execute
    request = self.session.post(self.url, **post_args)
              ^^^^^^^^^^^^^^^^^^^^^^^^^^^^^^^^^^^^^^^^
  File "/Users/zend/Desktop/faster-pytorch/.pixi/envs/default/lib/python3.12/site-packages/requests/sessions.py", line 637, in post
    return self.request("POST", url, data=data, json=json, **kwargs)
           ^^^^^^^^^^^^^^^^^^^^^^^^^^^^^^^^^^^^^^^^^^^^^^^^^^^^^^^^^
  File "/Users/zend/Desktop/faster-pytorch/.pixi/envs/default/lib/python3.12/site-packages/requests/sessions.py", line 589, in request
    resp = self.send(prep, **send_kwargs)
           ^^^^^^^^^^^^^^^^^^^^^^^^^^^^^^
  File "/Users/zend/Desktop/faster-pytorch/.pixi/envs/default/lib/python3.12/site-packages/requests/sessions.py", line 703, in send
    r = adapter.send(request, **kwargs)
        ^^^^^^^^^^^^^^^^^^^^^^^^^^^^^^^
  File "/Users/zend/Desktop/faster-pytorch/.pixi/envs/default/lib/python3.12/site-packages/requests/adapters.py", line 682, in send
    raise ConnectionError(err, request=request)
requests.exceptions.ConnectionError: ('Connection aborted.', ConnectionResetError(54, 'Connection reset by peer'))
2024-07-20 16:46:43,754 ERROR   MainThread:23323 [wandb_init.py:init():779] encountered error: Run initialization has timed out after 90.0 sec. 
Please refer to the documentation for additional information: https://docs.wandb.ai/guides/track/tracking-faq#initstarterror-error-communicating-with-wandb-process-
2024-07-20 16:46:43,757 ERROR   MainThread:23323 [wandb_init.py:init():1191] error in wandb.init()
Traceback (most recent call last):
  File "/Users/zend/Desktop/faster-pytorch/.pixi/envs/default/lib/python3.12/site-packages/wandb/sdk/wandb_init.py", line 1181, in init
    return wi.init()
           ^^^^^^^^^
  File "/Users/zend/Desktop/faster-pytorch/.pixi/envs/default/lib/python3.12/site-packages/wandb/sdk/wandb_init.py", line 785, in init
    raise error
wandb.errors.CommError: Run initialization has timed out after 90.0 sec. 
Please refer to the documentation for additional information: https://docs.wandb.ai/guides/track/tracking-faq#initstarterror-error-communicating-with-wandb-process-
2024-07-20 16:46:49,033 INFO    MainThread:23323 [wandb_settings.py:_apply_login():1935] Applying login settings: {}
2024-07-20 16:46:49,040 INFO    MainThread:23323 [wandb_setup.py:_flush():76] Current SDK version is 0.17.5
2024-07-20 16:46:49,040 INFO    MainThread:23323 [wandb_setup.py:_flush():76] Configure stats pid to 23323
2024-07-20 16:46:49,040 INFO    MainThread:23323 [wandb_setup.py:_flush():76] Loading settings from /Users/zend/.config/wandb/settings
2024-07-20 16:46:49,040 INFO    MainThread:23323 [wandb_setup.py:_flush():76] Loading settings from /Users/zend/Desktop/faster-pytorch/01Wandb/wandb/settings
2024-07-20 16:46:49,041 INFO    MainThread:23323 [wandb_setup.py:_flush():76] Loading settings from environment variables: {}
2024-07-20 16:46:49,041 INFO    MainThread:23323 [wandb_setup.py:_flush():76] Applying setup settings: {'_disable_service': False}
2024-07-20 16:46:49,041 INFO    MainThread:23323 [wandb_setup.py:_flush():76] Inferring run settings from compute environment: {'program': '<python with no main file>'}
2024-07-20 16:46:49,041 INFO    MainThread:23323 [wandb_setup.py:_flush():76] Applying login settings: {}
2024-07-20 16:46:49,041 INFO    MainThread:23323 [wandb_init.py:_log_setup():529] Logging user logs to /Users/zend/Desktop/faster-pytorch/01Wandb/wandb/run-20240720_164649-k44l8zqf/logs/debug.log
2024-07-20 16:46:49,041 INFO    MainThread:23323 [wandb_init.py:_log_setup():530] Logging internal logs to /Users/zend/Desktop/faster-pytorch/01Wandb/wandb/run-20240720_164649-k44l8zqf/logs/debug-internal.log
2024-07-20 16:46:49,041 INFO    MainThread:23323 [wandb_init.py:init():569] calling init triggers
2024-07-20 16:46:49,041 INFO    MainThread:23323 [wandb_init.py:init():576] wandb.init called with sweep_config: {}
config: {'lr': 0.0001, 'epoch': 3, 'batch_size': 64}
2024-07-20 16:46:49,041 INFO    MainThread:23323 [wandb_init.py:init():619] starting backend
2024-07-20 16:46:49,041 INFO    MainThread:23323 [wandb_init.py:init():623] setting up manager
2024-07-20 16:46:49,042 INFO    MainThread:23323 [backend.py:_multiprocessing_setup():105] multiprocessing start_methods=spawn,fork,forkserver, using: spawn
2024-07-20 16:46:49,042 INFO    MainThread:23323 [wandb_init.py:init():631] backend started and connected
2024-07-20 16:46:49,050 INFO    MainThread:23323 [wandb_run.py:_label_probe_notebook():1334] probe notebook
2024-07-20 16:46:49,050 INFO    MainThread:23323 [wandb_run.py:_label_probe_notebook():1344] Unable to probe notebook: 'NoneType' object has no attribute 'get'
2024-07-20 16:46:49,051 INFO    MainThread:23323 [wandb_init.py:init():720] updated telemetry
2024-07-20 16:46:49,051 INFO    MainThread:23323 [wandb_init.py:init():753] communicating run to backend with 90.0 second timeout
2024-07-20 16:48:19,524 ERROR   MainThread:23323 [wandb_init.py:init():779] encountered error: Run initialization has timed out after 90.0 sec. 
Please refer to the documentation for additional information: https://docs.wandb.ai/guides/track/tracking-faq#initstarterror-error-communicating-with-wandb-process-
2024-07-20 16:48:19,525 ERROR   MainThread:23323 [wandb_init.py:init():1191] error in wandb.init()
Traceback (most recent call last):
  File "/Users/zend/Desktop/faster-pytorch/.pixi/envs/default/lib/python3.12/site-packages/wandb/sdk/wandb_init.py", line 1181, in init
    return wi.init()
           ^^^^^^^^^
  File "/Users/zend/Desktop/faster-pytorch/.pixi/envs/default/lib/python3.12/site-packages/wandb/sdk/wandb_init.py", line 785, in init
    raise error
wandb.errors.CommError: Run initialization has timed out after 90.0 sec. 
Please refer to the documentation for additional information: https://docs.wandb.ai/guides/track/tracking-faq#initstarterror-error-communicating-with-wandb-process-
2024-07-20 16:48:31,135 INFO    MainThread:23323 [wandb_settings.py:_apply_login():1935] Applying login settings: {}
2024-07-20 16:48:31,140 INFO    MainThread:23323 [wandb_setup.py:_flush():76] Current SDK version is 0.17.5
2024-07-20 16:48:31,140 INFO    MainThread:23323 [wandb_setup.py:_flush():76] Configure stats pid to 23323
2024-07-20 16:48:31,141 INFO    MainThread:23323 [wandb_setup.py:_flush():76] Loading settings from /Users/zend/.config/wandb/settings
2024-07-20 16:48:31,141 INFO    MainThread:23323 [wandb_setup.py:_flush():76] Loading settings from /Users/zend/Desktop/faster-pytorch/01Wandb/wandb/settings
2024-07-20 16:48:31,141 INFO    MainThread:23323 [wandb_setup.py:_flush():76] Loading settings from environment variables: {}
2024-07-20 16:48:31,141 INFO    MainThread:23323 [wandb_setup.py:_flush():76] Applying setup settings: {'_disable_service': False}
2024-07-20 16:48:31,141 INFO    MainThread:23323 [wandb_setup.py:_flush():76] Inferring run settings from compute environment: {'program': '<python with no main file>'}
2024-07-20 16:48:31,141 INFO    MainThread:23323 [wandb_setup.py:_flush():76] Applying login settings: {}
2024-07-20 16:48:31,141 INFO    MainThread:23323 [wandb_init.py:_log_setup():529] Logging user logs to /Users/zend/Desktop/faster-pytorch/01Wandb/wandb/run-20240720_164831-d9zrywgv/logs/debug.log
2024-07-20 16:48:31,141 INFO    MainThread:23323 [wandb_init.py:_log_setup():530] Logging internal logs to /Users/zend/Desktop/faster-pytorch/01Wandb/wandb/run-20240720_164831-d9zrywgv/logs/debug-internal.log
2024-07-20 16:48:31,141 INFO    MainThread:23323 [wandb_init.py:init():569] calling init triggers
2024-07-20 16:48:31,141 INFO    MainThread:23323 [wandb_init.py:init():576] wandb.init called with sweep_config: {}
config: {'lr': 0.0001, 'epoch': 3, 'batch_size': 64}
2024-07-20 16:48:31,141 INFO    MainThread:23323 [wandb_init.py:init():619] starting backend
2024-07-20 16:48:31,141 INFO    MainThread:23323 [wandb_init.py:init():623] setting up manager
2024-07-20 16:48:31,143 INFO    MainThread:23323 [backend.py:_multiprocessing_setup():105] multiprocessing start_methods=spawn,fork,forkserver, using: spawn
2024-07-20 16:48:31,143 INFO    MainThread:23323 [wandb_init.py:init():631] backend started and connected
2024-07-20 16:48:31,150 INFO    MainThread:23323 [wandb_run.py:_label_probe_notebook():1334] probe notebook
2024-07-20 16:48:31,150 INFO    MainThread:23323 [wandb_run.py:_label_probe_notebook():1344] Unable to probe notebook: 'NoneType' object has no attribute 'get'
2024-07-20 16:48:31,150 INFO    MainThread:23323 [wandb_init.py:init():720] updated telemetry
2024-07-20 16:48:31,151 INFO    MainThread:23323 [wandb_init.py:init():753] communicating run to backend with 90.0 second timeout
